2021-03-18 14:29:13,018 ERROR: Exception on / [GET] [in C:\Users\carles\Anaconda3\lib\site-packages\flask\app.py:1891]
Traceback (most recent call last):
  File "C:\Users\carles\Anaconda3\lib\site-packages\flask\app.py", line 2446, in wsgi_app
    response = self.full_dispatch_request()
  File "C:\Users\carles\Anaconda3\lib\site-packages\flask\app.py", line 1951, in full_dispatch_request
    rv = self.handle_user_exception(e)
  File "C:\Users\carles\Anaconda3\lib\site-packages\flask\app.py", line 1820, in handle_user_exception
    reraise(exc_type, exc_value, tb)
  File "C:\Users\carles\Anaconda3\lib\site-packages\flask\_compat.py", line 39, in reraise
    raise value
  File "C:\Users\carles\Anaconda3\lib\site-packages\flask\app.py", line 1949, in full_dispatch_request
    rv = self.dispatch_request()
  File "C:\Users\carles\Anaconda3\lib\site-packages\flask\app.py", line 1935, in dispatch_request
    return self.view_functions[rule.endpoint](**req.view_args)
  File "C:\Users\carles\Anaconda3\lib\site-packages\flask_login\utils.py", line 272, in decorated_view
    return func(*args, **kwargs)
  File "D:\UNI\FEINA\Python\mega_tutorial\app\routes.py", line 53, in index
    prev_url=prev_url)
  File "C:\Users\carles\Anaconda3\lib\site-packages\flask\templating.py", line 140, in render_template
    ctx.app,
  File "C:\Users\carles\Anaconda3\lib\site-packages\flask\templating.py", line 120, in _render
    rv = template.render(context)
  File "C:\Users\carles\Anaconda3\lib\site-packages\jinja2\asyncsupport.py", line 76, in render
    return original_render(self, *args, **kwargs)
  File "C:\Users\carles\Anaconda3\lib\site-packages\jinja2\environment.py", line 1008, in render
    return self.environment.handle_exception(exc_info, True)
  File "C:\Users\carles\Anaconda3\lib\site-packages\jinja2\environment.py", line 780, in handle_exception
    reraise(exc_type, exc_value, tb)
  File "C:\Users\carles\Anaconda3\lib\site-packages\jinja2\_compat.py", line 37, in reraise
    raise value.with_traceback(tb)
  File "D:\UNI\FEINA\Python\mega_tutorial\app\templates\index.html", line 1, in top-level template code
    {% extends "base.html" %}
  File "C:\Users\carles\Anaconda3\lib\site-packages\jinja2\environment.py", line 1005, in render
    return concat(self.root_render_func(self.new_context(vars)))
  File "D:\UNI\FEINA\Python\mega_tutorial\app\templates\index.html", line 14, in root
    </p>
  File "D:\UNI\FEINA\Python\mega_tutorial\app\templates\base.html", line 14, in root
    <span class="icon-bar"></span>
  File "C:\Users\carles\Anaconda3\lib\site-packages\flask_bootstrap\templates\bootstrap\base.html", line 10, in root
    <meta name="viewport" content="width=device-width, initial-scale=1.0">
  File "C:\Users\carles\Anaconda3\lib\site-packages\flask_bootstrap\templates\bootstrap\base.html", line 20, in block_doc
    {% block body -%}
  File "C:\Users\carles\Anaconda3\lib\site-packages\flask_bootstrap\templates\bootstrap\base.html", line 39, in block_html
  File "C:\Users\carles\Anaconda3\lib\site-packages\flask_bootstrap\templates\bootstrap\base.html", line 90, in block_body
  File "D:\UNI\FEINA\Python\mega_tutorial\app\templates\base.html", line 67, in block_navbar
    text: $(sourceElem).text(),
  File "C:\Users\carles\Anaconda3\lib\site-packages\jinja2\runtime.py", line 262, in call
    return __obj(*args, **kwargs)
  File "C:\Users\carles\Anaconda3\lib\site-packages\flask\helpers.py", line 370, in url_for
    return appctx.app.handle_url_build_error(error, endpoint, values)
  File "C:\Users\carles\Anaconda3\lib\site-packages\flask\app.py", line 2215, in handle_url_build_error
    reraise(exc_type, exc_value, tb)
  File "C:\Users\carles\Anaconda3\lib\site-packages\flask\_compat.py", line 39, in reraise
    raise value
  File "C:\Users\carles\Anaconda3\lib\site-packages\flask\helpers.py", line 358, in url_for
    endpoint, values, method=method, force_external=external
  File "C:\Users\carles\Anaconda3\lib\site-packages\werkzeug\routing.py", line 2020, in build
    raise BuildError(endpoint, values, method, self)
werkzeug.routing.BuildError: Could not build url for endpoint 'auth.logout'. Did you mean 'logout' instead?
2021-03-18 14:29:13,452 ERROR: Exception on /favicon.ico [GET] [in C:\Users\carles\Anaconda3\lib\site-packages\flask\app.py:1891]
Traceback (most recent call last):
  File "C:\Users\carles\Anaconda3\lib\site-packages\flask\app.py", line 1949, in full_dispatch_request
    rv = self.dispatch_request()
  File "C:\Users\carles\Anaconda3\lib\site-packages\flask\app.py", line 1925, in dispatch_request
    self.raise_routing_exception(req)
  File "C:\Users\carles\Anaconda3\lib\site-packages\flask\app.py", line 1907, in raise_routing_exception
    raise request.routing_exception
  File "C:\Users\carles\Anaconda3\lib\site-packages\flask\ctx.py", line 350, in match_request
    result = self.url_adapter.match(return_rule=True)
  File "C:\Users\carles\Anaconda3\lib\site-packages\werkzeug\routing.py", line 1799, in match
    raise NotFound()
werkzeug.exceptions.NotFound: 404 Not Found: The requested URL was not found on the server. If you entered the URL manually please check your spelling and try again.

During handling of the above exception, another exception occurred:

Traceback (most recent call last):
  File "C:\Users\carles\Anaconda3\lib\site-packages\flask\app.py", line 2446, in wsgi_app
    response = self.full_dispatch_request()
  File "C:\Users\carles\Anaconda3\lib\site-packages\flask\app.py", line 1951, in full_dispatch_request
    rv = self.handle_user_exception(e)
  File "C:\Users\carles\Anaconda3\lib\site-packages\flask\app.py", line 1815, in handle_user_exception
    return self.handle_http_exception(e)
  File "C:\Users\carles\Anaconda3\lib\site-packages\flask\app.py", line 1743, in handle_http_exception
    return handler(e)
  File "D:\UNI\FEINA\Python\mega_tutorial\app\errors.py", line 13, in not_found_error
    return render_template('404.html'), 404
  File "C:\Users\carles\Anaconda3\lib\site-packages\flask\templating.py", line 140, in render_template
    ctx.app,
  File "C:\Users\carles\Anaconda3\lib\site-packages\flask\templating.py", line 120, in _render
    rv = template.render(context)
  File "C:\Users\carles\Anaconda3\lib\site-packages\jinja2\asyncsupport.py", line 76, in render
    return original_render(self, *args, **kwargs)
  File "C:\Users\carles\Anaconda3\lib\site-packages\jinja2\environment.py", line 1008, in render
    return self.environment.handle_exception(exc_info, True)
  File "C:\Users\carles\Anaconda3\lib\site-packages\jinja2\environment.py", line 780, in handle_exception
    reraise(exc_type, exc_value, tb)
  File "C:\Users\carles\Anaconda3\lib\site-packages\jinja2\_compat.py", line 37, in reraise
    raise value.with_traceback(tb)
  File "D:\UNI\FEINA\Python\mega_tutorial\app\templates\404.html", line 1, in top-level template code
    {% extends "base.html" %}
  File "C:\Users\carles\Anaconda3\lib\site-packages\jinja2\environment.py", line 1005, in render
    return concat(self.root_render_func(self.new_context(vars)))
  File "D:\UNI\FEINA\Python\mega_tutorial\app\templates\404.html", line 14, in root
  File "D:\UNI\FEINA\Python\mega_tutorial\app\templates\base.html", line 14, in root
    <span class="icon-bar"></span>
  File "C:\Users\carles\Anaconda3\lib\site-packages\flask_bootstrap\templates\bootstrap\base.html", line 10, in root
    <meta name="viewport" content="width=device-width, initial-scale=1.0">
  File "C:\Users\carles\Anaconda3\lib\site-packages\flask_bootstrap\templates\bootstrap\base.html", line 20, in block_doc
    {% block body -%}
  File "C:\Users\carles\Anaconda3\lib\site-packages\flask_bootstrap\templates\bootstrap\base.html", line 39, in block_html
  File "C:\Users\carles\Anaconda3\lib\site-packages\flask_bootstrap\templates\bootstrap\base.html", line 90, in block_body
  File "D:\UNI\FEINA\Python\mega_tutorial\app\templates\base.html", line 67, in block_navbar
    text: $(sourceElem).text(),
  File "C:\Users\carles\Anaconda3\lib\site-packages\jinja2\runtime.py", line 262, in call
    return __obj(*args, **kwargs)
  File "C:\Users\carles\Anaconda3\lib\site-packages\flask\helpers.py", line 370, in url_for
    return appctx.app.handle_url_build_error(error, endpoint, values)
  File "C:\Users\carles\Anaconda3\lib\site-packages\flask\app.py", line 2215, in handle_url_build_error
    reraise(exc_type, exc_value, tb)
  File "C:\Users\carles\Anaconda3\lib\site-packages\flask\_compat.py", line 39, in reraise
    raise value
  File "C:\Users\carles\Anaconda3\lib\site-packages\flask\helpers.py", line 358, in url_for
    endpoint, values, method=method, force_external=external
  File "C:\Users\carles\Anaconda3\lib\site-packages\werkzeug\routing.py", line 2020, in build
    raise BuildError(endpoint, values, method, self)
werkzeug.routing.BuildError: Could not build url for endpoint 'auth.logout'. Did you mean 'logout' instead?
