2021-03-11 15:35:08,728 INFO: Microblog startup [in D:\UNI\FEINA\Python\mega_tutorial\app\__init__.py:56]
2021-03-11 15:35:41,734 ERROR: Exception on /explore [GET] [in C:\Users\carles\Anaconda3\lib\site-packages\flask\app.py:1891]
Traceback (most recent call last):
  File "C:\Users\carles\Anaconda3\lib\site-packages\flask\app.py", line 2446, in wsgi_app
    response = self.full_dispatch_request()
  File "C:\Users\carles\Anaconda3\lib\site-packages\flask\app.py", line 1951, in full_dispatch_request
    rv = self.handle_user_exception(e)
  File "C:\Users\carles\Anaconda3\lib\site-packages\flask\app.py", line 1820, in handle_user_exception
    reraise(exc_type, exc_value, tb)
  File "C:\Users\carles\Anaconda3\lib\site-packages\flask\_compat.py", line 39, in reraise
    raise value
  File "C:\Users\carles\Anaconda3\lib\site-packages\flask\app.py", line 1949, in full_dispatch_request
    rv = self.dispatch_request()
  File "C:\Users\carles\Anaconda3\lib\site-packages\flask\app.py", line 1935, in dispatch_request
    return self.view_functions[rule.endpoint](**req.view_args)
  File "C:\Users\carles\Anaconda3\lib\site-packages\flask_login\utils.py", line 272, in decorated_view
    return func(*args, **kwargs)
  File "D:\UNI\FEINA\Python\mega_tutorial\app\routes.py", line 41, in explore
    return render_template('index.html', title='Explore', posts=posts)
  File "C:\Users\carles\Anaconda3\lib\site-packages\flask\templating.py", line 140, in render_template
    ctx.app,
  File "C:\Users\carles\Anaconda3\lib\site-packages\flask\templating.py", line 120, in _render
    rv = template.render(context)
  File "C:\Users\carles\Anaconda3\lib\site-packages\jinja2\asyncsupport.py", line 76, in render
    return original_render(self, *args, **kwargs)
  File "C:\Users\carles\Anaconda3\lib\site-packages\jinja2\environment.py", line 1008, in render
    return self.environment.handle_exception(exc_info, True)
  File "C:\Users\carles\Anaconda3\lib\site-packages\jinja2\environment.py", line 780, in handle_exception
    reraise(exc_type, exc_value, tb)
  File "C:\Users\carles\Anaconda3\lib\site-packages\jinja2\_compat.py", line 37, in reraise
    raise value.with_traceback(tb)
  File "D:\UNI\FEINA\Python\mega_tutorial\app\templates\index.html", line 1, in top-level template code
    {% extends "base.html" %}
  File "C:\Users\carles\Anaconda3\lib\site-packages\jinja2\environment.py", line 1005, in render
    return concat(self.root_render_func(self.new_context(vars)))
  File "D:\UNI\FEINA\Python\mega_tutorial\app\templates\index.html", line 14, in root
    </p>
  File "D:\UNI\FEINA\Python\mega_tutorial\app\templates\base.html", line 55, in root
  File "D:\UNI\FEINA\Python\mega_tutorial\app\templates\index.html", line 48, in block_content
  File "D:\UNI\FEINA\Python\mega_tutorial\app\templates\_post.html", line 13, in root
  File "C:\Users\carles\Anaconda3\lib\site-packages\jinja2\runtime.py", line 262, in call
    return __obj(*args, **kwargs)
  File "C:\Users\carles\Anaconda3\lib\site-packages\jinja2\runtime.py", line 630, in _fail_with_undefined_error
    raise self._undefined_exception(hint)
jinja2.exceptions.UndefinedError: 'None' has no attribute 'avatar'
2021-03-11 16:16:30,173 INFO: Microblog startup [in D:\UNI\FEINA\Python\mega_tutorial\app\__init__.py:56]
2021-03-11 16:16:41,306 ERROR: Exception on /explore [GET] [in C:\Users\carles\Anaconda3\lib\site-packages\flask\app.py:1891]
Traceback (most recent call last):
  File "C:\Users\carles\Anaconda3\lib\site-packages\flask\app.py", line 2446, in wsgi_app
    response = self.full_dispatch_request()
  File "C:\Users\carles\Anaconda3\lib\site-packages\flask\app.py", line 1951, in full_dispatch_request
    rv = self.handle_user_exception(e)
  File "C:\Users\carles\Anaconda3\lib\site-packages\flask\app.py", line 1820, in handle_user_exception
    reraise(exc_type, exc_value, tb)
  File "C:\Users\carles\Anaconda3\lib\site-packages\flask\_compat.py", line 39, in reraise
    raise value
  File "C:\Users\carles\Anaconda3\lib\site-packages\flask\app.py", line 1949, in full_dispatch_request
    rv = self.dispatch_request()
  File "C:\Users\carles\Anaconda3\lib\site-packages\flask\app.py", line 1935, in dispatch_request
    return self.view_functions[rule.endpoint](**req.view_args)
  File "C:\Users\carles\Anaconda3\lib\site-packages\flask_login\utils.py", line 272, in decorated_view
    return func(*args, **kwargs)
  File "D:\UNI\FEINA\Python\mega_tutorial\app\routes.py", line 41, in explore
    return render_template('index.html', title='Explore', posts=posts)
  File "C:\Users\carles\Anaconda3\lib\site-packages\flask\templating.py", line 140, in render_template
    ctx.app,
  File "C:\Users\carles\Anaconda3\lib\site-packages\flask\templating.py", line 120, in _render
    rv = template.render(context)
  File "C:\Users\carles\Anaconda3\lib\site-packages\jinja2\asyncsupport.py", line 76, in render
    return original_render(self, *args, **kwargs)
  File "C:\Users\carles\Anaconda3\lib\site-packages\jinja2\environment.py", line 1008, in render
    return self.environment.handle_exception(exc_info, True)
  File "C:\Users\carles\Anaconda3\lib\site-packages\jinja2\environment.py", line 780, in handle_exception
    reraise(exc_type, exc_value, tb)
  File "C:\Users\carles\Anaconda3\lib\site-packages\jinja2\_compat.py", line 37, in reraise
    raise value.with_traceback(tb)
  File "D:\UNI\FEINA\Python\mega_tutorial\app\templates\index.html", line 1, in top-level template code
    {% extends "base.html" %}
  File "C:\Users\carles\Anaconda3\lib\site-packages\jinja2\environment.py", line 1005, in render
    return concat(self.root_render_func(self.new_context(vars)))
  File "D:\UNI\FEINA\Python\mega_tutorial\app\templates\index.html", line 14, in root
    </p>
  File "D:\UNI\FEINA\Python\mega_tutorial\app\templates\base.html", line 55, in root
  File "D:\UNI\FEINA\Python\mega_tutorial\app\templates\index.html", line 48, in block_content
  File "D:\UNI\FEINA\Python\mega_tutorial\app\templates\_post.html", line 13, in root
  File "C:\Users\carles\Anaconda3\lib\site-packages\jinja2\runtime.py", line 262, in call
    return __obj(*args, **kwargs)
  File "C:\Users\carles\Anaconda3\lib\site-packages\jinja2\runtime.py", line 630, in _fail_with_undefined_error
    raise self._undefined_exception(hint)
jinja2.exceptions.UndefinedError: 'None' has no attribute 'avatar'
2021-03-11 16:24:12,911 INFO: Microblog startup [in D:\UNI\FEINA\Python\mega_tutorial\app\__init__.py:56]
